Workbook

Sheet 요약
A1: Lore — 원가 및 사용량 기반 비용 추정
A2: 작성 기준: 실제 API 호출 로그 실측치 + 사용량 가정. 노란 셀과 파란 글씨 셀만 수정하면 전체가 다시 계산됩니다.
A4: 적용 단가 시나리오 | B4: =단가!C4 -> 여유(재시도 반영) | C4: ← 단가 시트 B4에서 1/2/3 으로 변경
A6: 1. 핵심 단가
A7: 항목 | B7: 적용 모드 | C7: ① 실측 | D7: ③ 보수 | E7: 설명
A8: 캐릭터 1개 셋업 (스토리 설계 + 시트) | B8: =단가!G21 -> 570 | C8: =단가!D21 -> 487 | D8: =단가!F21 -> 700 | E8: 캐릭터당 최초 1회만 발생
A9: 웹툰 1화 (콘티 + 그림 12컷) | B9: =단가!G22 -> 1530 | C9: =단가!D22 -> 1125 | D9: =단가!F22 -> 2404 | E9: 캐릭터 재사용 시 화당 원가
A10: 유저 첫 경험 총액 (캐릭터 + 1화) | B10: =단가!G23 -> 2100 | C10: =단가!D23 -> 1612 | D10: =단가!F23 -> 3104 | E10: 신규 유저 1명을 온보딩하는 데 드는 원가
A11: 이미지 1장 재생성 (그냥) | B11: =단가!G13 -> 195 | C11: =단가!D13 -> 188 | D11: =단가!F13 -> 250 | E11: 컷 3개 묶음 단위 · 재생성 최소 단위
A12: 이미지 1장 재생성 (피드백 반영) | B12: =단가!G14 -> 225 | C12: =단가!D14 -> 202 | D12: =단가!F14 -> 290 | E12: 프롬프트 재작성 텍스트 콜이 추가로 붙음
A13: 화 콘티 전체 재작성 | B13: =단가!G16 -> 430 | C13: =단가!D16 -> 347 | D13: =단가!F16 -> 500 | E13: 스토리가 마음에 안 들 때
A14: 화 통째로 재생성 (콘티 + 그림) | B14: =단가!G24 -> 1530 | C14: =단가!D24 -> 1125 | D14: =단가!F24 -> 2404 | E14: 가장 비싼 단일 재생성 액션
A15: 캐릭터 시트 재생성 | B15: =단가!G19 -> 220 | C15: =단가!D19 -> 188 | D15: =단가!F19 -> 300 | E15: 후보 장수를 늘리면 배수로 증가
A17: 2. 활성 유저 1명당 월 원가
A18: 유저 타입 | B18: 구성 비율 | C18: 월 1인 원가 | D18: 연 환산 | E18: 타입 정의
A19: =비용추정!A5 -> 체험형 | B19: =비용추정!B5 -> 0.6 | C19: =비용추정!F5 -> 2754 | D19: =C19*12 -> 33048 | E19: =사용가정!J8 -> 자캐 하나 넣어보고 1화만 뽑아보는 유입 유저
A20: =비용추정!A6 -> 일반형 | B20: =비용추정!B6 -> 0.3 | C20: =비용추정!F6 -> 7876.5 | D20: =C20*12 -> 94518 | E20: =사용가정!J9 -> 자캐 커뮤니티 활동 유저. 마음에 드는 컷은 다시 뽑음
A21: =비용추정!A7 -> 헤비형 | B21: =비용추정!B7 -> 0.1 | C21: =비용추정!F7 -> 20664 | D21: =C21*12 -> 247968 | E21: =사용가정!J10 -> 연재하듯 쓰는 코어 유저. 재생성 비중이 가장 큼
A22: 가중평균 | C22: =비용추정!F8 -> 6081.75 | D22: =C22*12 -> 72981
A24: 3. 규모별 월 총 원가 (API 원가만)
A25: 단계 | B25: 가입 유저수 | C25: 활성 유저수 | D25: 월 총 원가 | E25: 연 환산
A26: =비용추정!A12 -> 검증 (현재 목표) | B26: =비용추정!B12 -> 10 | C26: =비용추정!C12 -> 6 | D26: =비용추정!G12 -> 36490.5 | E26: =D26*12 -> 437886
A27: =비용추정!A13 -> 클로즈드 베타 | B27: =비용추정!B13 -> 50 | C27: =비용추정!C13 -> 30 | D27: =비용추정!G13 -> 182452.5 | E27: =D27*12 -> 2189430
A28: =비용추정!A14 -> 오픈 베타 | B28: =비용추정!B14 -> 200 | C28: =비용추정!C14 -> 120 | D28: =비용추정!G14 -> 729810 | E28: =D28*12 -> 8757720
A29: =비용추정!A15 -> 확산 | B29: =비용추정!B15 -> 500 | C29: =비용추정!C15 -> 300 | D29: =비용추정!G15 -> 1824525 | E29: =D29*12 -> 21894300
A30: =비용추정!A16 -> 확산 + | B30: =비용추정!B16 -> 1000 | C30: =비용추정!C16 -> 600 | D30: =비용추정!G16 -> 3649050 | E30: =D30*12 -> 43788600
A33: 4. 읽는 법
A34: ① 단가 시트 — 실제 API 로그에서 뽑은 단계별 원가. B4에서 실측/여유/보수 모드를 전환합니다.
A35: ② 사용가정 시트 — 유저 타입별 월 사용 횟수. 여기가 유일한 '추정' 영역이며, 8/19 유저 검증 이후 실측으로 교체할 자리입니다.
A36: ③ 비용추정 시트 — 단가 × 사용량 × 유저수. 가입 유저수만 바꾸면 전체가 다시 계산됩니다.
A37: ④ 민감도 시트 — 규모별 총액과 기능별 원가 비중.
A39: 색 규칙: 파란 글씨 = 직접 입력 / 검정 = 수식 / 초록 = 다른 시트 참조 / 노란 배경 = 핵심 가정
A41: 5. 크레딧 요약
A42: 항목 | B42: 값 | E42: 메모
A43: 1크레딧 기준 원가 | B43: =크레딧설계!$B$4 -> 200 | E43: 이미지 1장 = 1크레딧
A44: 웹툰 1화 | B44: =크레딧설계!$C$9&"크레딧" -> 8크레딧 | E44: 서비스의 기본 단위
A45: 이미지 1장 재생성 | B45: =크레딧설계!$C$11&"크레딧" -> 1크레딧 | E45: 재생성 최소 단위
A46: 신규 가입 무료 지급 | B46: =크레딧설계!$B$27&"크레딧" -> 12크레딧 | E46: 첫 경험 1바퀴
A47: 유저 1명 체험 원가 | B47: =크레딧설계!$C$27 -> 2400 | E47: 무료 유저 1명 획득 비용
A48: Lore 패스 원가율 | B48: =크레딧설계!$G$44 -> 0.4040404 | E48: 월 9,900원 / 25크레딧 기준
...

Sheet 단가
A1: Lore 단가표 — API 실측 원가 기준
A2: 단위: 원(KRW). 파란 글씨 = 직접 입력값 / 검정 = 수식. 모든 실측치는 실제 API 호출 로그 집계값.
A4: 시나리오 모드 (1=실측 · 2=여유 · 3=보수) | B4: 2 | C4: =CHOOSE(B4,"실측(오늘 완주 기준)","여유(재시도 반영)","보수(최악 케이스)") -> 여유(재시도 반영)
A6: 항목 | B6: 단위 | C6: 주 모델 | D6: ① 실측 | E6: ② 여유 | F6: ③ 보수 | G6: 적용 단가 | H6: 산출 근거 / 가정
A7: 【 신규 생성 】
A8: 스토리 설계 (LOOK·SEED·P1·P3·SCENE) | B8: 캐릭터 1개 | C8: gpt-4.1 | D8: 299 | E8: 350 | F8: 400 | G8: =CHOOSE($B$4,D8,E8,F8) -> 350 | H8: 실측 299원 = LOOK 12 + SEED 9 + P1 43×3(게이트 재시도) + P3 34 + SCENE 73. 재시도 없으면 약 190원.
A9: 캐릭터 시트 | B9: 캐릭터 1개 (1장) | C9: gpt-image-2 (예정) | D9: 188 | E9: 220 | F9: 300 | G9: =CHOOSE($B$4,D9,E9,F9) -> 220 | H9: 실측 188원은 gemini-2.5-flash-image 기준. gpt-image-2로 고정 예정이라 ②③에 단가 상승분 반영(미실측 가정).
A10: 콘티 (W4~W8) | B10: 1화 | C10: gpt-4.1 | D10: 347 | E10: 430 | F10: 500 | G10: =CHOOSE($B$4,D10,E10,F10) -> 430 | H10: 실측 347원 = W4 33(시리즈당 1회) + W5 39 + W6 21 + W7 116~131×2회. 재시도 없으면 216원.
A11: 그림 (4장 × 3컷 = 12컷) | B11: 1화 | C11: gemini-3-pro-image-preview | D11: 778 | E11: 1100 | F11: 1904 | G11: =CHOOSE($B$4,D11,E11,F11) -> 1100 | H11: 실측 778원(장당 195·컷당 65) = 이미지 4장 + 컷→영문 변환 14원. 별도 실측 1,904원 케이스 존재 → ③에 반영.
A12: 【 재생성 】
A13: 이미지 1장 재생성 (그냥 다시) | B13: 1장 (컷 3개) | C13: gemini-3-pro-image-preview | D13: 188 | E13: 195 | F13: 250 | G13: =CHOOSE($B$4,D13,E13,F13) -> 195 | H13: 동일 프롬프트로 재호출. 이미지 모델 1콜만 발생.
A14: 이미지 1장 재생성 (피드백 반영) | B14: 1장 (컷 3개) | C14: 이미지 + gpt-4.1 | D14: 202 | E14: 225 | F14: 290 | G14: =CHOOSE($B$4,D14,E14,F14) -> 225 | H14: 가정: 이미지 재생성 단가 + 피드백→프롬프트 재작성 텍스트 콜 14~40원. 텍스트 콜은 미실측 추정치.
A15: 컷 분해(W7)만 재시도 | B15: 1회 | C15: gpt-4.1 | D15: 116 | E15: 131 | F15: 180 | G15: =CHOOSE($B$4,D15,E15,F15) -> 131 | H15: 실측 116~131원/회.
A16: 화 콘티 전체 재작성 (W5~W8) | B16: 1화 | C16: gpt-4.1 | D16: 347 | E16: 430 | F16: 500 | G16: =CHOOSE($B$4,D16,E16,F16) -> 430 | H16: 실측 216원(순조) ~ 347원(W7 1회 추가 재시도).
A17: 스토리 1단계만 재생성 (SCENE 등) | B17: 1회 | C17: gpt-4.1 | D17: 33 | E17: 40 | F17: 60 | G17: =CHOOSE($B$4,D17,E17,F17) -> 40 | H17: 실측 SCENE 33~40원/회.
A18: 캐릭터 전체 재설계 | B18: 캐릭터 1개 | C18: gpt-4.1 | D18: 299 | E18: 350 | F18: 400 | G18: =CHOOSE($B$4,D18,E18,F18) -> 350 | H18: 실측 190원(순조) ~ 299원(재시도 포함).
A19: 캐릭터 시트 재생성 | B19: 1장 | C19: gpt-image-2 (예정) | D19: 188 | E19: 220 | F19: 300 | G19: =CHOOSE($B$4,D19,E19,F19) -> 220 | H19: 후보 장수(candidates=N)를 늘리면 N배로 증가.
A20: 【 조합 단가 (자동 계산) 】
A21: 캐릭터 1개 셋업 (스토리 설계 + 시트) | B21: 캐릭터 1개 | C21: — | D21: =D8+D9 -> 487 | E21: =E8+E9 -> 570 | F21: =F8+F9 -> 700 | G21: =CHOOSE($B$4,D21,E21,F21) -> 570 | H21: 캐릭터당 최초 1회. 이후 화에서 재사용.
A22: 웹툰 1화 (콘티 + 그림) | B22: 1화 | C22: — | D22: =D10+D11 -> 1125 | E22: =E10+E11 -> 1530 | F22: =F10+F11 -> 2404 | G22: =CHOOSE($B$4,D22,E22,F22) -> 1530 | H22: 캐릭터가 이미 있는 상태에서 1화를 뽑는 원가.
A23: 첫 화 총액 (캐릭터 셋업 + 1화) | B23: 유저 첫 경험 | C23: — | D23: =D21+D22 -> 1612 | E23: =E21+E22 -> 2100 | F23: =F21+F22 -> 3104 | G23: =CHOOSE($B$4,D23,E23,F23) -> 2100 | H23: 실측 모드에서 1,612원 — 오늘 완주값과 일치.
A24: 화 1개 통째 재생성 (콘티 + 그림) | B24: 1화 | C24: — | D24: =D16+D11 -> 1125 | E24: =E16+E11 -> 1530 | F24: =F16+F11 -> 2404 | G24: =CHOOSE($B$4,D24,E24,F24) -> 1530 | H24: 실측 기준 994~1,125원.
A26: ※ 참고: 기존에 쓰던 '1화 1,424원'은 화마다 스토리 설계를 다시 도는 경우입니다. 캐릭터를 재사용하면 화당 원가는 위 '웹툰 1화' 값이 맞습니다.
A27: ※ 표본: 스토리 설계 18회 / 캐릭터 시트 9회 / 콘티 12회 / 그림 17화의 실제 API 호출 로그 집계. 비용 로그가 없는 초기 테스트 배치는 제외.
A28: ※ 환율 가정: 1,400원/USD (누적 46,023원 ≈ $32.87 기준).

Sheet 사용가정
A1: 사용 시나리오 가정 — 유저 타입별 월 사용량
A2: 파란 글씨 셀만 수정하세요. 아래 수치는 실사용 데이터가 없는 상태의 계획 가정치입니다 (8/19 자캐 유저 10명 검증 이후 실측으로 교체 예정).
A4: 가입자 대비 활성률 | B4: 0.6 | C4: 가입만 하고 한 번도 생성하지 않는 유저 제외 비율
A5: 집계 기간 | B5: 월 1회 | C5: 아래 사용 횟수는 모두 '활성 유저 1명이 한 달 동안' 기준
A7: 유저 타입 | B7: 구성 비율 | C7: 캐릭터 신규 | D7: 시트 재생성 | E7: 웹툰 화수 | F7: 스토리 단계 재생성 | G7: 콘티 재시도 | H7: 이미지 재생성 (그냥) | I7: 이미지 재생성 (피드백) | J7: 타입 정의
A8: 체험형 | B8: 0.6 | C8: 1 | D8: 0.3 | E8: 1 | F8: 0.5 | G8: 0.5 | H8: 2 | I8: 0.5 | J8: 자캐 하나 넣어보고 1화만 뽑아보는 유입 유저
A9: 일반형 | B9: 0.3 | C9: 2 | D9: 1 | E9: 3 | F9: 2 | G9: 1.5 | H9: 5 | I9: 3 | J9: 자캐 커뮤니티 활동 유저. 마음에 드는 컷은 다시 뽑음
A10: 헤비형 | B10: 0.1 | C10: 4 | D10: 2 | E10: 8 | F10: 5 | G10: 4 | H10: 14 | I10: 10 | J10: 연재하듯 쓰는 코어 유저. 재생성 비중이 가장 큼
A11: 합계 (100%가 되어야 함) | B11: =SUM(B8:B10) -> 1 | C11: =IF(ABS(B11-1)<0.001,"OK","비율 합계를 100%로 맞추세요") -> OK
A13: 가정 근거
A14: · 구성 비율 60/30/10: 실사용 데이터 없음. UGC 창작 서비스의 통상적인 롱테일 분포를 준용한 계획 가정치.
A15: · 재생성 횟수: 그림 품질 게이트가 화당 평균 1~2회 걸린 개발 로그를 근거로, 유저는 그보다 더 자주 다시 뽑는다고 가정.
A16: · 피드백 재생성 비율을 별도 분리한 이유: 텍스트 콜이 추가로 붙어 단가가 다르기 때문.
A17: · 월 기준으로 잡은 이유: API 과금과 예산 집행이 모두 월 단위이기 때문.

Sheet 비용추정
A1: 원가 추정 — 유저 타입별 · 규모별
A2: 초록 글씨 = 다른 시트 참조. 세 개 열(실측/여유/보수)은 단가 시트의 모드 선택과 무관하게 항상 동시에 계산됩니다.
A4: 유저 타입 | B4: 구성 비율 | C4: ① 실측 기준 | D4: ② 여유 기준 | E4: ③ 보수 기준 | F4: 월 1인 원가 (적용 모드)
A5: =사용가정!A8 -> 체험형 | B5: =사용가정!B8 -> 0.6 | C5: =사용가정!C8*(단가!$D$8+단가!$D$9)+사용가정!D8*단가!$D$19+사용가정!E8*(단가!$D$10+단가!$D$11)+사용가정!F8*단가!$D$17+사용가정!G8*단가!$D$15+사용가정!H8*단가!$D$13+사용가정!I8*단가!$D$14 -> 2219.9 | D5: =사용가정!C8*(단가!$E$8+단가!$E$9)+사용가정!D8*단가!$E$19+사용가정!E8*(단가!$E$10+단가!$E$11)+사용가정!F8*단가!$E$17+사용가정!G8*단가!$E$15+사용가정!H8*단가!$E$13+사용가정!I8*단가!$E$14 -> 2754 | E5: =사용가정!C8*(단가!$F$8+단가!$F$9)+사용가정!D8*단가!$F$19+사용가정!E8*(단가!$F$10+단가!$F$11)+사용가정!F8*단가!$F$17+사용가정!G8*단가!$F$15+사용가정!H8*단가!$F$13+사용가정!I8*단가!$F$14 -> 3959 | F5: =CHOOSE(단가!$B$4,C5,D5,E5) -> 2754
A6: =사용가정!A9 -> 일반형 | B6: =사용가정!B9 -> 0.3 | C6: =사용가정!C9*(단가!$D$8+단가!$D$9)+사용가정!D9*단가!$D$19+사용가정!E9*(단가!$D$10+단가!$D$11)+사용가정!F9*단가!$D$17+사용가정!G9*단가!$D$15+사용가정!H9*단가!$D$13+사용가정!I9*단가!$D$14 -> 6323 | D6: =사용가정!C9*(단가!$E$8+단가!$E$9)+사용가정!D9*단가!$E$19+사용가정!E9*(단가!$E$10+단가!$E$11)+사용가정!F9*단가!$E$17+사용가정!G9*단가!$E$15+사용가정!H9*단가!$E$13+사용가정!I9*단가!$E$14 -> 7876.5 | E6: =사용가정!C9*(단가!$F$8+단가!$F$9)+사용가정!D9*단가!$F$19+사용가정!E9*(단가!$F$10+단가!$F$11)+사용가정!F9*단가!$F$17+사용가정!G9*단가!$F$15+사용가정!H9*단가!$F$13+사용가정!I9*단가!$F$14 -> 11422 | F6: =CHOOSE(단가!$B$4,C6,D6,E6) -> 7876.5
A7: =사용가정!A10 -> 헤비형 | B7: =사용가정!B10 -> 0.1 | C7: =사용가정!C10*(단가!$D$8+단가!$D$9)+사용가정!D10*단가!$D$19+사용가정!E10*(단가!$D$10+단가!$D$11)+사용가정!F10*단가!$D$17+사용가정!G10*단가!$D$15+사용가정!H10*단가!$D$13+사용가정!I10*단가!$D$14 -> 16605 | D7: =사용가정!C10*(단가!$E$8+단가!$E$9)+사용가정!D10*단가!$E$19+사용가정!E10*(단가!$E$10+단가!$E$11)+사용가정!F10*단가!$E$17+사용가정!G10*단가!$E$15+사용가정!H10*단가!$E$13+사용가정!I10*단가!$E$14 -> 20664 | E7: =사용가정!C10*(단가!$F$8+단가!$F$9)+사용가정!D10*단가!$F$19+사용가정!E10*(단가!$F$10+단가!$F$11)+사용가정!F10*단가!$F$17+사용가정!G10*단가!$F$15+사용가정!H10*단가!$F$13+사용가정!I10*단가!$F$14 -> 30052 | F7: =CHOOSE(단가!$B$4,C7,D7,E7) -> 20664
A8: 가중평균 (활성 유저 1명) | B8: =SUM(B5:B7) -> 1 | C8: =SUMPRODUCT($B$5:$B$7,C5:C7) -> 4889.34 | D8: =SUMPRODUCT($B$5:$B$7,D5:D7) -> 6081.75 | E8: =SUMPRODUCT($B$5:$B$7,E5:E7) -> 8807.2 | F8: =CHOOSE(단가!$B$4,C8,D8,E8) -> 6081.75
A10: 규모별 월 총 원가
A11: 단계 | B11: 가입 유저수 | C11: 활성 유저수 | D11: ① 실측 기준 | E11: ② 여유 기준 | F11: ③ 보수 기준 | G11: 적용 모드 총액 | H11: 활성 1인당
A12: 검증 (현재 목표) | B12: 10 | C12: =B12*사용가정!$B$4 -> 6 | D12: =$C12*C$8 -> 29336.04 | E12: =$C12*D$8 -> 36490.5 | F12: =$C12*E$8 -> 52843.2 | G12: =CHOOSE(단가!$B$4,D12,E12,F12) -> 36490.5 | H12: =IFERROR(G12/C12,0) -> 6081.75
A13: 클로즈드 베타 | B13: 50 | C13: =B13*사용가정!$B$4 -> 30 | D13: =$C13*C$8 -> 146680.2 | E13: =$C13*D$8 -> 182452.5 | F13: =$C13*E$8 -> 264216 | G13: =CHOOSE(단가!$B$4,D13,E13,F13) -> 182452.5 | H13: =IFERROR(G13/C13,0) -> 6081.75
A14: 오픈 베타 | B14: 200 | C14: =B14*사용가정!$B$4 -> 120 | D14: =$C14*C$8 -> 586720.8 | E14: =$C14*D$8 -> 729810 | F14: =$C14*E$8 -> 1056864 | G14: =CHOOSE(단가!$B$4,D14,E14,F14) -> 729810 | H14: =IFERROR(G14/C14,0) -> 6081.75
A15: 확산 | B15: 500 | C15: =B15*사용가정!$B$4 -> 300 | D15: =$C15*C$8 -> 1466802 | E15: =$C15*D$8 -> 1824525 | F15: =$C15*E$8 -> 2642160 | G15: =CHOOSE(단가!$B$4,D15,E15,F15) -> 1824525 | H15: =IFERROR(G15/C15,0) -> 6081.75
A16: 확산 + | B16: 1000 | C16: =B16*사용가정!$B$4 -> 600 | D16: =$C16*C$8 -> 2933604 | E16: =$C16*D$8 -> 3649050 | F16: =$C16*E$8 -> 5284320 | G16: =CHOOSE(단가!$B$4,D16,E16,F16) -> 3649050 | H16: =IFERROR(G16/C16,0) -> 6081.75
A18: ※ '가입 유저수'(파란 셀)만 바꾸면 나머지는 전부 자동 계산됩니다.
A19: ※ 총액은 API 원가만 포함합니다. 서버·스토리지·CDN 비용은 별도입니다.

Sheet 크레딧설계
A1: 크레딧 설계 — 액션 가격표 · 무료 정책 · 유료 플랜
A2: 설계 원칙: 1크레딧 = 이미지 1장. 유저가 '무엇에 돈이 나가는지' 화면을 안 봐도 알 수 있어야 합니다.
A4: 1크레딧 기준 원가 | B4: 200 | C4: 이미지 1장(컷 3개) 재생성 원가에 맞춘 값
A5: 적용 단가 모드 | B5: =단가!C4 -> 여유(재시도 반영)
A7: A. 액션별 크레딧 가격표
A8: 액션 | B8: 실원가 (적용모드) | C8: 크레딧 | D8: 크레딧 환산액 | E8: 원가 커버율 | H8: 설계 의도
A9: 웹툰 1화 생성 (12컷 · 이미지 4장) | B9: =단가!G22 -> 1530 | C9: 8 | D9: =C9*$B$4 -> 1600 | E9: =IFERROR(D9/B9,0) -> 1.0457516 | H9: 이미지 4장(4) + 콘티 텍스트(2) + 여유(2). 서비스의 기본 단위.
A10: 캐릭터 생성 (스토리 설계 + 시트) | B10: =단가!G21 -> 570 | C10: 3 | D10: =C10*$B$4 -> 600 | E10: =IFERROR(D10/B10,0) -> 1.0526316 | H10: 캐릭터당 최초 1회. 이후 모든 화에 재사용되므로 싸게 가져감.
A11: 이미지 1장 재생성 (컷 3개) | B11: =단가!G13 -> 195 | C11: 1 | D11: =C11*$B$4 -> 200 | E11: =IFERROR(D11/B11,0) -> 1.025641 | H11: 크레딧 정의의 기준점. 이 값이 흔들리면 전체 가격표가 흔들립니다.
A12: 이미지 1장 재생성 + 피드백 반영 | B12: =단가!G14 -> 225 | C12: 2 | D12: =C12*$B$4 -> 400 | E12: =IFERROR(D12/B12,0) -> 1.7777778 | H12: 원가 차이는 30원뿐이지만 유저 가치가 훨씬 큼. 가치 기반 가산 (원가 근거 아님).
A13: 캐릭터 시트 재생성 | B13: =단가!G19 -> 220 | C13: 1 | D13: =C13*$B$4 -> 200 | E13: =IFERROR(D13/B13,0) -> 0.90909091 | H13: 같은 '이미지 1장'이므로 동일 가격. 후보 장수는 1장으로 고정해야 이 가격이 유지됩니다.
A14: 화 콘티 전체 재작성 (스토리만 다시) | B14: =단가!G16 -> 430 | C14: 2 | D14: =C14*$B$4 -> 400 | E14: =IFERROR(D14/B14,0) -> 0.93023256 | H14: 그림 없이 텍스트만. 그림 재생성보다 싸게 해서 '스토리부터 고치기'를 유도.
A15: 스토리 단계 재생성 (SCENE 등) | B15: =단가!G17 -> 40 | C15: 0 | D15: =C15*$B$4 -> 0 | E15: =IFERROR(D15/B15,0) -> 0 | H15: 원가 40원. 무료(일 10회 상한). 싼 곳에서 후하게 풀어야 서비스가 관대하게 느껴집니다.
A16: 화 통째 재생성 (콘티 + 그림) | B16: =단가!G24 -> 1530 | C16: 10 | D16: =C16*$B$4 -> 2000 | E16: =IFERROR(D16/B16,0) -> 1.3071895 | H16: 가장 비싼 단일 액션. 실행 전 확인 모달 필요.
A17: ※ 커버율 100% 미만 = 그 액션은 팔수록 손해입니다. 단가 모드를 ③보수로 바꿔보면 어디가 먼저 무너지는지 보입니다.
A19: B. 화질 등급 배수 (제타의 '모델 변경'에 해당하는 축)
A20: 등급 | B20: 이미지 모델 | C20: 크레딧 배수 | D20: 1화 크레딧 | E20: 실측 여부
A21: 스탠다드 | B21: gemini-2.5-flash-image | C21: 0.6 | D21: =ROUND($C$9*C21,0) -> 5 | E21: 미실측 — 추정치. 측정 후 확정 필요
A22: 프리미엄 (현재 기본) | B22: gemini-3-pro-image-preview | C22: 1 | D22: =ROUND($C$9*C22,0) -> 8 | E22: 실측 완료. 현재 모든 단가의 기준
A23: ※ 스탠다드 단가를 실측해야 이 등급제가 실제로 성립합니다. 지금은 구조만 잡아둔 상태입니다.
A25: C. 무료 크레딧 정책
A26: 항목 | B26: 크레딧 | C26: 원가 | H26: 근거
A27: 신규 가입 지급 (1회) | B27: 12 | C27: =B27*$B$4 -> 2400 | H27: 캐릭터 1개(3) + 1화(8) + 재생성 1회(1) = 첫 경험 정확히 1바퀴. 유저 1명 체험 원가 = 이 금액.
A28: 월 무료 리필 | B28: 3 | C28: =B28*$B$4 -> 600 | H28: 재방문 유도용 최소치. 1화를 못 뽑는 양이라 의도적으로 부족하게 설계.
A29: ※ 광고 시청에는 크레딧을 지급하지 않습니다. 제타가 광고로 피스를 후하게 주는 건 텍스트 채팅이라 1피스 원가가 수원대이기 때문입니다. 우리는 크레딧당 200원, 국내 리워드 광고는 뷰당 10~20원이라 광고 1회에 1크레딧을 주면 회당 180원 적자입니다.
A31: C-2. 광고 보상 — 비크레딧 방식
A32: 크레딧 대신 '원가가 0에 가까우면서 유료 결제 이유를 갉아먹지 않는' 보상만 지급합니다.
A33: 보상 | B33: 채택 | C33: 추가 원가 | D33: 패스 혜택과 충돌 | H33: 설계 메모
A34: 워터마크 제거 1회권 (특정 화 1개) | B34: 채택 | C34: 0원 | D34: 없음 | H34: 영구 제거가 아니라 화 단위 1회. 상시 제거는 패스 전용으로 남겨두기 때문에 결제 이유를 침범하지 않습니다. '이 화 예쁘게 나왔으니 깨끗하게 저장하고 싶다'는 순간에 광고가 붙어 타이밍도 자연스럽습니다.
A35: 생성 대기열 우선 | B35: 채택 | C35: 0원 | D35: 없음 | H35: 큐 순서만 앞당김. 원가는 0인데 체감은 큽니다. 유저가 몰릴수록 가치가 올라가는 보상이라 초기엔 효과가 약합니다.
A36: 저장 슬롯 확대 | B36: 채택 | C36: 스토리지만 | D36: 없음 | H36: 캐릭터·화 보관 개수 상향. API 원가는 발생하지 않고 스토리지 비용만 늘어납니다.
A37: 공개 갤러리 상단 노출 | B37: 보류 | C37: 0원 | D37: 없음 | H37: 커뮤니티 기능 도입 여부가 아직 미정. 갤러리를 넣기로 결정한 뒤에 다시 검토합니다.
A38: 워터마크 영구 제거 | B38: 미채택 | C38: 0원 | D38: 충돌 | H38: 패스 혜택과 정면으로 겹칩니다. 광고 몇 번으로 유료 결제 이유가 대체되므로 광고 보상으로 쓰지 않습니다.
A39: 크레딧 지급 | B39: 미채택 | C39: 회당 180원 적자 | D39: — | H39: 위 ※ 참고. 광고 10회당 1크레딧이 손익분기인데, 그건 유저 입장에서 사실상 없는 보상입니다.
A40: ※ 원칙: 광고 보상과 패스 혜택은 겹치면 안 됩니다. 겹치는 순간 광고가 결제를 대체합니다.
A41: ※ 이 설계에서는 광고가 원가를 늘리지 않으므로, 광고 매출은 요금제손익 시트에 반영하지 않은 순수 상방입니다.
A42: D. 유료 플랜
A43: 플랜 | B43: 월 가격 | C43: 지급 크레딧 | D43: 소진율 | E43: 실사용 크레딧 | F43: 원가 | G43: 원가율 | H43: 1인 월 마진
A44: Lore 패스 | B44: 9900 | C44: 25 | D44: 0.8 | E44: =C44*D44 -> 20 | F44: =E44*$B$4 -> 4000 | G44: =IFERROR(F44/B44,0) -> 0.4040404 | H44: =B44-F44 -> 5900
A45: Lore 패스+ | B45: 19900 | C45: 55 | D45: 0.85 | E45: =C45*D45 -> 46.75 | F45: =E45*$B$4 -> 9350 | G45: =IFERROR(F45/B45,0) -> 0.46984925 | H45: =B45-F45 -> 10550
...

Sheet 요금제손익
A1: 요금제 손익 — 유저 구성 × 규모
A2: 보수적으로 구독 매출만 계산합니다(충전 매출 미포함). 서버·스토리지 비용도 제외된 API 기준 손익입니다.
A4: 무료 유저 월 소진 크레딧 | B4: 4 | C4: 월 리필 3 + 광고 보상 일부. 무료 유저는 매출 0이므로 이 값이 순수 비용입니다.
A6: 1. 활성 유저 구성과 1인당 월 손익
A7: 유저 구분 | B7: 구성 비율 | C7: 월 매출 | D7: 월 원가 | E7: 월 마진 | F7: 마진율
A8: 무료 | B8: 0.85 | C8: =0 -> 0 | D8: =$B$4*크레딧설계!$B$4 -> 800 | E8: =C8-D8 -> -800 | F8: =IFERROR(E8/C8,0) -> 0
A9: Lore 패스 | B9: 0.12 | C9: =크레딧설계!$B$44 -> 9900 | D9: =크레딧설계!$F$44 -> 4000 | E9: =C9-D9 -> 5900 | F9: =IFERROR(E9/C9,0) -> 0.5959596
A10: Lore 패스+ | B10: 0.03 | C10: =크레딧설계!$B$45 -> 19900 | D10: =크레딧설계!$F$45 -> 9350 | E10: =C10-D10 -> 10550 | F10: =IFERROR(E10/C10,0) -> 0.53015075
A11: 가중평균 (활성 1인) | B11: =SUM(B8:B10) -> 1 | C11: =SUMPRODUCT($B$8:$B$10,C8:C10) -> 1785 | D11: =SUMPRODUCT($B$8:$B$10,D8:D10) -> 1440.5 | E11: =SUMPRODUCT($B$8:$B$10,E8:E10) -> 344.5 | F11: =IFERROR(E11/C11,0) -> 0.1929972
A13: 2. 규모별 월 손익
A14: 단계 | B14: 가입 유저수 | C14: 활성 유저수 | D14: 월 매출 | E14: 월 원가 | F14: 월 마진 | G14: 마진율 | H14: 유료 유저수
A15: =비용추정!A12 -> 검증 (현재 목표) | B15: =비용추정!B12 -> 10 | C15: =비용추정!C12 -> 6 | D15: =$C15*$C$11 -> 10710 | E15: =$C15*$D$11 -> 8643 | F15: =D15-E15 -> 2067 | G15: =IFERROR(F15/D15,0) -> 0.1929972 | H15: =$C15*(B9+B10) -> 0.9
A16: =비용추정!A13 -> 클로즈드 베타 | B16: =비용추정!B13 -> 50 | C16: =비용추정!C13 -> 30 | D16: =$C16*$C$11 -> 53550 | E16: =$C16*$D$11 -> 43215 | F16: =D16-E16 -> 10335 | G16: =IFERROR(F16/D16,0) -> 0.1929972 | H16: =$C16*(B9+B10) -> 4.5
A17: =비용추정!A14 -> 오픈 베타 | B17: =비용추정!B14 -> 200 | C17: =비용추정!C14 -> 120 | D17: =$C17*$C$11 -> 214200 | E17: =$C17*$D$11 -> 172860 | F17: =D17-E17 -> 41340 | G17: =IFERROR(F17/D17,0) -> 0.1929972 | H17: =$C17*(B9+B10) -> 18
A18: =비용추정!A15 -> 확산 | B18: =비용추정!B15 -> 500 | C18: =비용추정!C15 -> 300 | D18: =$C18*$C$11 -> 535500 | E18: =$C18*$D$11 -> 432150 | F18: =D18-E18 -> 103350 | G18: =IFERROR(F18/D18,0) -> 0.1929972 | H18: =$C18*(B9+B10) -> 45
A19: =비용추정!A16 -> 확산 + | B19: =비용추정!B16 -> 1000 | C19: =비용추정!C16 -> 600 | D19: =$C19*$C$11 -> 1071000 | E19: =$C19*$D$11 -> 864300 | F19: =D19-E19 -> 206700 | G19: =IFERROR(F19/D19,0) -> 0.1929972 | H19: =$C19*(B9+B10) -> 90
A21: 3. 손익분기 유료 전환율
A22: 무료 유저 1명당 월 비용 | B22: =$B$4*크레딧설계!$B$4 -> 800
A23: 패스 유저 1명당 월 마진 | B23: =크레딧설계!$H$44 -> 5900
A24: 필요 최소 전환율 | B24: =IFERROR(B22/(B22+B23),0) -> 0.11940299
A25: 현재 가정 전환율 | B25: =B9+B10 -> 0.15
A26: =IF(B25>=B24,"현재 가정으로 흑자","적자 — 무료 크레딧을 줄이거나 원가를 내려야 함") -> 현재 가정으로 흑자
A28: ※ 이 표의 핵심은 '무료 유저 비용을 유료 유저 마진이 몇 명분 감당하느냐'입니다. 무료 크레딧이 후할수록 필요 전환율이 급격히 올라갑니다.
A29: ※ 구성 비율(85/12/3)은 실사용 데이터 없는 가정치입니다. 국내 앱 구독 전환율은 통상 한 자릿수라 12%는 낙관에 가깝습니다 — 낮춰보면서 감당 가능한지 확인하세요.

Sheet 민감도
A1: 민감도 — 유저 규모 × 단가 시나리오
A2: 활성률과 유저 타입 구성은 사용가정 시트 값을 그대로 사용합니다.
A4: 활성 유저수 | B4: ① 실측 기준 | C4: ② 여유 기준 | D4: ③ 보수 기준 | F4: 기능별 원가 비중 (활성 유저 1명 · 적용 모드)
A5: 10 | B5: =$A5*비용추정!C$8 -> 48893.4 | C5: =$A5*비용추정!D$8 -> 60817.5 | D5: =$A5*비용추정!E$8 -> 88072 | F5: 기능 | G5: 월 1인 원가 | H5: 비중
A6: 25 | B6: =$A6*비용추정!C$8 -> 122233.5 | C6: =$A6*비용추정!D$8 -> 152043.75 | D6: =$A6*비용추정!E$8 -> 220180 | F6: 캐릭터 셋업 (스토리 설계 + 시트) | G6: =SUMPRODUCT(사용가정!$B$8:$B$10,사용가정!$C$8:$C$10)*(단가!$G$8+단가!$G$9) -> 912 | H6: =IFERROR(G6/$G$13,0) -> 0.14995684
A7: 50 | B7: =$A7*비용추정!C$8 -> 244467 | C7: =$A7*비용추정!D$8 -> 304087.5 | D7: =$A7*비용추정!E$8 -> 440360 | F7: 웹툰 화 생성 (콘티 + 그림) | G7: =SUMPRODUCT(사용가정!$B$8:$B$10,사용가정!$E$8:$E$10)*(단가!$G$10+단가!$G$11) -> 3519 | H7: =IFERROR(G7/$G$13,0) -> 0.57861635
A8: 100 | B8: =$A8*비용추정!C$8 -> 488934 | C8: =$A8*비용추정!D$8 -> 608175 | D8: =$A8*비용추정!E$8 -> 880720 | F8: 이미지 재생성 (그냥) | G8: =SUMPRODUCT(사용가정!$B$8:$B$10,사용가정!$H$8:$H$10)*단가!$G$13 -> 799.5 | H8: =IFERROR(G8/$G$13,0) -> 0.13145887
A9: 200 | B9: =$A9*비용추정!C$8 -> 977868 | C9: =$A9*비용추정!D$8 -> 1216350 | D9: =$A9*비용추정!E$8 -> 1761440 | F9: 이미지 재생성 (피드백) | G9: =SUMPRODUCT(사용가정!$B$8:$B$10,사용가정!$I$8:$I$10)*단가!$G$14 -> 495 | H9: =IFERROR(G9/$G$13,0) -> 0.081391047
A10: 300 | B10: =$A10*비용추정!C$8 -> 1466802 | C10: =$A10*비용추정!D$8 -> 1824525 | D10: =$A10*비용추정!E$8 -> 2642160 | F10: 콘티 재시도 (W7) | G10: =SUMPRODUCT(사용가정!$B$8:$B$10,사용가정!$G$8:$G$10)*단가!$G$15 -> 150.65 | H10: =IFERROR(G10/$G$13,0) -> 0.024770831
A11: 500 | B11: =$A11*비용추정!C$8 -> 2444670 | C11: =$A11*비용추정!D$8 -> 3040875 | D11: =$A11*비용추정!E$8 -> 4403600 | F11: 스토리 단계 재생성 | G11: =SUMPRODUCT(사용가정!$B$8:$B$10,사용가정!$F$8:$F$10)*단가!$G$17 -> 56 | H11: =IFERROR(G11/$G$13,0) -> 0.009207876
A12: 1000 | B12: =$A12*비용추정!C$8 -> 4889340 | C12: =$A12*비용추정!D$8 -> 6081750 | D12: =$A12*비용추정!E$8 -> 8807200 | F12: 캐릭터 시트 재생성 | G12: =SUMPRODUCT(사용가정!$B$8:$B$10,사용가정!$D$8:$D$10)*단가!$G$19 -> 149.6 | H12: =IFERROR(G12/$G$13,0) -> 0.024598183
F13: 합계 | G13: =SUM(G6:G12) -> 6081.75 | H13: =SUM(H6:H12) -> 1
F15: ※ 비중이 가장 큰 항목이 원가 관리의 1순위 대상입니다.
F16: ※ 그림 단계는 개발 로그에서도 전체 누적 비용의 64%를 차지했습니다.
